<?xml version="1.0" ?>
<robot xmlns:xacro="http://ros.org/wiki/xacro">

<link name="base_link">

</link>

<link name="base_footprint_link">

</link>

<joint name="base_footprint_joint" type="fixed">
  <parent link="base_link"/>
  <child link="base_footprint_link"/>
  <origin xyz="0 0 0" rpy="0 0 0"/>
</joint>

<link
    name="chassis_link">
    <inertial>
      <origin
        xyz="0.0016049 7.4296E-14 0.058697"
        rpy="0 0 0" />
      <mass
        value="12" />
      <inertia
        ixx="0.37085"
        ixy="5.9421E-08"
        ixz="-0.0043358"
        iyy="0.56013"
        iyz="1.0073E-08"
        izz="0.86077" />
    </inertial>
    <visual>
      <origin
        xyz="0 0 0"
        rpy="0 0 0" />
      <geometry>
        <mesh
          filename="package://simulation_pkg/models/base_link.STL" />
      </geometry>
      <material
        name="">
        <color
          rgba="0.29804 0.29804 0.29804 1" />
      </material>
    </visual>
    <collision>
      <origin
        xyz="0 0 0"
        rpy="0 0 0" />
      <geometry>
        <mesh
          filename="package://simulation_pkg/models/base_link.STL" />
      </geometry>
    </collision>
  </link>

  <joint name="chassis_joint" type="fixed">
    <parent link="base_link"/>
    <child link="chassis_link"/>
    <origin xyz="0 0 0"/>
  </joint>

  <link
    name="right_wheel_link">
    <inertial>
      <origin
        xyz="1.3878E-17 0 -0.0033337"
        rpy="0 0 0" />
      <mass
        value="0.60765" />
      <inertia
        ixx="0.0012132"
        ixy="-1.1019E-20"
        ixz="5.4221E-19"
        iyy="0.0012132"
        iyz="-7.6446E-20"
        izz="0.0022643" />
    </inertial>
    <visual>
      <origin
        xyz="0 0 0"
        rpy="0 0 0" />
      <geometry>
        <mesh
          filename="package://simulation_pkg/models/right_wheel_link.STL" />
      </geometry>
      <material
        name="">
        <color
          rgba="0.29804 0.29804 0.29804 1" />
      </material>
    </visual>
    <collision>
      <origin
        xyz="0 0 0"
        rpy="0 0 0" />
      <geometry>
        <sphere radius="0.08"/>
      </geometry>
    </collision>
  </link>

  <joint
    name="right_wheel_joint"
    type="continuous">
    <origin
      xyz="0 -0.21525 0.059"
      rpy="1.5708 0 0" />
    <parent
      link="chassis_link" />
    <child
      link="right_wheel_link" />
    <axis
      xyz="0 0 -1" />
    <limit
      effort="10"
      velocity="10" />
    <dynamics
      damping="0.1"
      friction="0.1" />
  </joint>

  <link
    name="left_wheel_link">
    <inertial>
      <origin
        xyz="6.9389E-18 0 -0.0033337"
        rpy="0 0 0" />
      <mass
        value="0.60765" />
      <inertia
        ixx="0.0012132"
        ixy="2.0023E-20"
        ixz="1.2266E-19"
        iyy="0.0012132"
        iyz="1.6778E-19"
        izz="0.0022643" />
    </inertial>
    <visual>
      <origin
        xyz="0 0 0"
        rpy="0 0 0" />
      <geometry>
        <mesh
          filename="package://simulation_pkg/models/left_wheel_link.STL" />
      </geometry>
      <material
        name="">
        <color
          rgba="0.29804 0.29804 0.29804 1" />
      </material>
    </visual>
    <collision>
      <origin
        xyz="0 0 0"
        rpy="0 0 0" />
      <geometry>
        <sphere radius="0.08"/>
      </geometry>
    </collision>
  </link>

  <joint
    name="left_wheel_joint"
    type="continuous">
    <origin
      xyz="0 0.21525 0.059"
      rpy="-1.5708 0 0" />
    <parent
      link="chassis_link" />
    <child
      link="left_wheel_link" />
    <axis
      xyz="0 0 1" />
    <limit
      effort="10"
      velocity="10" />
    <dynamics
      damping="0.1"
      friction="0.1" />
  </joint>

  <link
    name="front_caster_link">
    <inertial>
      <origin
        xyz="-1.7347E-18 0.0030758 -0.00021456"
        rpy="0 0 0" />
      <mass
        value="0.05" />
      <inertia
        ixx="3.1756E-06"
        ixy="-4.0907E-23"
        ixz="-7.1759E-22"
        iyy="6.1712E-06"
        iyz="-5.9858E-09"
        izz="3.1557E-06" />
    </inertial>
    <visual>
      <origin
        xyz="0 0 0"
        rpy="0 0 0" />
      <geometry>
        <mesh
          filename="package://simulation_pkg/models/front_caster_link.STL" />
      </geometry>
      <material
        name="">
        <color
          rgba="0.75294 0.75294 0.75294 1" />
      </material>
    </visual>
    <collision>
      <origin
        xyz="0 0 0"
        rpy="0 0 0" />
      <geometry>
        <mesh
          filename="package://simulation_pkg/models/front_caster_link.STL" />
      </geometry>
    </collision>
  </link>

  <joint
    name="front_caster_joint"
    type="fixed">
    <origin
      xyz="0.24008 0 -0.0075"
      rpy="1.5708 0 1.5708" />
    <parent
      link="chassis_link" />
    <child
      link="front_caster_link" />
    <axis
      xyz="0 0 0" />
    <dynamics
      damping="0"
      friction="0.001" />
  </joint>

  <link
    name="rear_caster_link">
    <inertial>
      <origin
        xyz="-3.2526E-19 0.0030758 -0.00021456"
        rpy="0 0 0" />
      <mass
        value="0.05" />
      <inertia
        ixx="3.1756E-06"
        ixy="-5.5022E-23"
        ixz="-1.1135E-21"
        iyy="6.1712E-06"
        iyz="-5.9858E-09"
        izz="3.1557E-06" />
    </inertial>
    <visual>
      <origin
        xyz="0 0 0"
        rpy="0 0 0" />
      <geometry>
        <mesh
          filename="package://simulation_pkg/models/rear_caster_link.STL" />
      </geometry>
      <material
        name="">
        <color
          rgba="0.75294 0.75294 0.75294 1" />
      </material>
    </visual>
    <collision>
      <origin
        xyz="0 0 0"
        rpy="0 0 0" />
      <geometry>
        <mesh
          filename="package://simulation_pkg/models/rear_caster_link.STL" />
      </geometry>
    </collision>
  </link>

  <joint
    name="rear_caster_joint"
    type="fixed">
    <origin
      xyz="-0.23992 0 -0.0075"
      rpy="1.5708 0 1.5708" />
    <parent
      link="chassis_link" />
    <child
      link="rear_caster_link" />
    <axis
      xyz="0 0 0" />
    <dynamics
      damping="0"
      friction="0.001" />
  </joint>

  <link
    name="lidar_link">
    <inertial>
      <origin
        xyz="2.7756E-17 -1.0842E-19 0.0045392"
        rpy="0 0 0" />
      <mass
        value="0.25" />
      <inertia
        ixx="4.9112E-05"
        ixy="0"
        ixz="-1.2331E-21"
        iyy="4.9112E-05"
        iyz="-4.2562E-37"
        izz="8.3852E-05" />
    </inertial>
    <visual>
      <origin
        xyz="0 0 0"
        rpy="0 0 0" />
      <geometry>
        <mesh
          filename="package://simulation_pkg/models/lidar_link.STL" />
      </geometry>
      <material
        name="">
        <color
          rgba="0.10196 0.10196 0.10196 1" />
      </material>
    </visual>
    <collision>
      <origin
        xyz="0 0 0"
        rpy="0 0 0" />
      <geometry>
        <mesh
          filename="package://simulation_pkg/models/lidar_link.STL" />
      </geometry>
    </collision>
  </link>

  <joint
    name="lidar_joint"
    type="fixed">
    <origin
      xyz="0.19 0 0.24025"
      rpy="0 0 0" />
    <parent
      link="chassis_link" />
    <child
      link="lidar_link" />
  </joint>
</robot>

